I'm sorry, but an uncaught exception occurred.

While running game code:
  File "game/script.rpy", line 445, in script
    Y "Really? I only thought we were just some delivery guys for a massive coporation."
Exception: Sayer 'Y' is not defined.

-- Full Traceback ------------------------------------------------------------

Full traceback:
  File "game/script.rpy", line 445, in script
    Y "Really? I only thought we were just some delivery guys for a massive coporation."
  File "D:\renpy-8.3.2-sdk\renpy\ast.py", line 2573, in execute
    Say.execute(self)
  File "D:\renpy-8.3.2-sdk\renpy\ast.py", line 575, in execute
    who = eval_who(self.who, self.who_fast)
  File "D:\renpy-8.3.2-sdk\renpy\ast.py", line 464, in eval_who
    raise Exception("Sayer '%s' is not defined." % who)
Exception: Sayer 'Y' is not defined.

Windows-10-10.0.22631 AMD64
Ren'Py 8.3.2.24090902
Spacial Delivery 1.0
Wed Nov 13 22:03:58 2024
